<?xml version="1.0" ?>
<sdf version="1.5">
  <model name="frc2018_robot">
    <static>false</static>

    <!-- Links -->
    <link name="chassis">

      <!-- Inertia -->
      <inertial>
        <mass>45.3592</mass>
        <inertia>
          <ixx>2.7851686</ixx>
          <ixy>0</ixy>
          <ixz>0</ixz>
          <iyy>1.9585429</iyy>
          <iyz>0</iyz>
          <izz>4.4737342</izz>
        </inertia>
      </inertial>

      <!-- Visuals -->
      <visual name="robot_visual">
        <geometry>
          <mesh>
            <uri>model://Gazebo2018/frc2018_robot/meshes/robot.obj</uri>
          </mesh>
        </geometry>
      </visual>

      <!-- Collision geometries -->
      <collision name='robot_collision'>
        <pose>0 0 0.129853 0 0 0</pose>
        <geometry>
          <box>
            <size>0.694572 0.837328 0.188976</size>
          </box>
        </geometry>
      </collision>

      <collision name='wheel_bl_collision'>
        <pose>-0.31847 -0.346192 0.060411 0 1.5707963 0</pose>
        <geometry>
          <cylinder>
            <radius>0.0508</radius>
            <length>0.03175</length>
          </cylinder>
        </geometry>
        <surface>
          <friction>
            <ode>
              <mu>0</mu>
              <mu2>0</mu2>
              <slip1>1.0</slip1>
              <slip2>1.0</slip2>
            </ode>
          </friction>
        </surface>
      </collision>

      <collision name='wheel_br_collision'>
        <pose>0.31484 -0.346192 0.060411 0 1.5707963 0</pose>
        <geometry>
          <cylinder>
            <radius>0.0508</radius>
            <length>0.03175</length>
          </cylinder>
        </geometry>
        <surface>
          <friction>
            <ode>
              <mu>0</mu>
              <mu2>0</mu2>
              <slip1>1.0</slip1>
              <slip2>1.0</slip2>
            </ode>
          </friction>
        </surface>
      </collision>
    </link>

    <link name='wheel_fl'>
      <inertial>
        <mass>0.11</mass>
        <inertia>
          <ixx>0.0001419</ixx>
          <ixy>0</ixy>
          <ixz>0</ixz>
          <iyy>0.0000733</iyy>
          <iyz>0</iyz>
          <izz>0.0000733</izz>
        </inertia>
      </inertial>
      <pose>-0.322842 0.339673 0.060411 0 1.5707963 0</pose>
      <collision name='wheel_fl_collision'>
        <geometry>
          <cylinder>
            <radius>0.0508</radius>
            <length>0.03175</length>
          </cylinder>
        </geometry>
      </collision>
    </link>

    <link name='wheel_fr'>
      <inertial>
        <mass>0.11</mass>
        <inertia>
          <ixx>0.0001419</ixx>
          <ixy>0</ixy>
          <ixz>0</ixz>
          <iyy>0.0000733</iyy>
          <iyz>0</iyz>
          <izz>0.0000733</izz>
        </inertia>
      </inertial>
      <pose>0.31916 0.339673 0.060411 0 1.5707963 0</pose>
      <collision name='wheel_fr_collision'>
        <geometry>
          <cylinder>
            <radius>0.0508</radius>
            <length>0.03175</length>
          </cylinder>
        </geometry>
      </collision>
    </link>

    <link name='wheel_ml'>
      <inertial>
        <mass>0.11</mass>
        <inertia>
          <ixx>0.0001419</ixx>
          <ixy>0</ixy>
          <ixz>0</ixz>
          <iyy>0.0000733</iyy>
          <iyz>0</iyz>
          <izz>0.0000733</izz>
        </inertia>
      </inertial>
      <pose>-0.322842 -0.004098 0.060411 0 1.5707963 0</pose>
      <collision name='wheel_ml_collision'>
        <geometry>
          <cylinder>
            <radius>0.0508</radius>
            <length>0.03175</length>
          </cylinder>
        </geometry>
      </collision>
    </link>

    <link name='wheel_mr'>
      <inertial>
        <mass>0.11</mass>
        <inertia>
          <ixx>0.0001419</ixx>
          <ixy>0</ixy>
          <ixz>0</ixz>
          <iyy>0.0000733</iyy>
          <iyz>0</iyz>
          <izz>0.0000733</izz>
        </inertia>
      </inertial>
      <pose>0.31916 -0.004098 0.060411 0 1.5707963 0</pose>
      <collision name='wheel_mr_collision'>
        <geometry>
          <cylinder>
            <radius>0.0508</radius>
            <length>0.03175</length>
          </cylinder>
        </geometry>
      </collision>
    </link>

    <!-- Sensors -->
    <link name='zed_camera'>
      <inertial>
        <mass>0.16007</mass>
        <inertia>
          <ixx>0.00039322</ixx>
          <ixy>0</ixy>
          <ixz>0</ixz>
          <iyy>2.5042E-05</iyy>
          <iyz>0</iyz>
          <izz>0.00039512</izz>
        </inertia>
      </inertial>
      <pose>0.3 0 0.3 0 0 0</pose>
      <visual name='zed_visual'>
        <geometry>
          <box>
            <size>0.175 0.03 0.033</size>
          </box>
        </geometry>
        <material>
          <ambient>1 0 0 1</ambient>
        </material>
      </visual>
      <collision name='zed_collision'>
        <geometry>
          <box>
            <size>0.175 0.03 0.033</size>
          </box>
        </geometry>
      </collision>
    </link>

    <!-- Joints -->
    <joint name="wheel_fl_joint" type="revolute">
      <pose>0 0 0 0 0 0</pose>
      <parent>chassis</parent>
      <child>wheel_fl</child>
      <axis>
        <xyz>0 0 -1</xyz>
      </axis>
    </joint>

    <joint name="wheel_fr_joint" type="revolute">
      <pose>0 0 0 0 0 0</pose>
      <parent>chassis</parent>
      <child>wheel_fr</child>
      <axis>
        <xyz>0 0 -1</xyz>
      </axis>
    </joint>

    <joint name="wheel_ml_joint" type="revolute">
      <pose>0 0 0 0 0 0</pose>
      <parent>chassis</parent>
      <child>wheel_ml</child>
      <axis>
        <xyz>0 0 -1</xyz>
      </axis>
    </joint>

    <joint name="wheel_mr_joint" type="revolute">
      <pose>0 0 0 0 0 0</pose>
      <parent>chassis</parent>
      <child>wheel_mr</child>
      <axis>
        <xyz>0 0 -1</xyz>
      </axis>
    </joint>

    <!-- Sensor Joints -->
    <joint name="zed_joint" type="fixed">
      <pose>0 0 0 0 0 0</pose>
      <parent>chassis</parent>
      <child>zed_camera</child>
    </joint>
    
  </model>
</sdf>
